---
title: "'Throw' 문은 'Catch' 문 외부 또는 'Finally' 문 내부에서 피연산자를 생략할 수 없습니다."
ms.date: 07/20/2015
f1_keywords:
- vbc30666
- bc30666
helpviewer_keywords:
- BC30666
ms.assetid: a208a6ea-0e36-4bf1-8984-4de1a0e38a2a
ms.openlocfilehash: 17e7817c608e9c3513e0320b62f42410613f33b0
ms.sourcegitcommit: 9b552addadfb57fab0b9e7852ed4f1f1b8a42f8e
ms.translationtype: MT
ms.contentlocale: ko-KR
ms.lasthandoff: 04/23/2019
ms.locfileid: "61666042"
---
# <a name="throw-statement-cannot-omit-operand-outside-a-catch-statement-or-inside-a-finally-statement"></a>'Throw' 문은 'Catch' 문 외부 또는 'Finally' 문 내부에서 피연산자를 생략할 수 없습니다.
`Throw` 문 외부의 `Catch` 문에서 예외 개체의 이름을 제공해야 합니다.  
  
 **오류 ID:** BC30666  
  
## <a name="to-correct-this-error"></a>이 오류를 해결하려면  
  
1. `System.Exception`에서 파생된 예외 개체의 이름을 지정합니다.  
  
2. `Throw` 문이 `Catch` 블록 내부에 있도록 코드를 재구성합니다.  
  
## <a name="see-also"></a>참고자료

- [Throw 문](../../visual-basic/language-reference/statements/throw-statement.md)
- [Try...Catch...Finally 문](../../visual-basic/language-reference/statements/try-catch-finally-statement.md)
- <xref:System.Exception?displayProperty=nameWithType>
- [.NET의 예외 처리 및 Throw](../../standard/exceptions/index.md)
